Workbook

Sheet Executive Analytics & KPIs
B1: TVS Certified - Conversion Analytics & Performance Intelligence
B2: January to September 2026 Executive Summary & Regional Conversion Metrics (4,314 Units)
B4: TOTAL CONVERTED | D4: AUCTION TURNOVER | F4: TVS INCOME (EX-GST) | H4: TVS INCOME (INCL-GST) | J4: AVG TVS MARGIN %
B5: =COUNTA('Conversion Analytics (Master)'!D4:D4317) | D5: =SUM('Conversion Analytics (Master)'!I4:I4317) | F5: =SUM('Conversion Analytics (Master)'!M4:M4317) | H5: =SUM('Conversion Analytics (Master)'!N4:N4317) | J5: =AVERAGE('Conversion Analytics (Master)'!O4:O4317)
B8: REGIONAL PERFORMANCE BREAKDOWN
B9: State | C9: Units Converted | D9: GMV (Turnover) | E9: TVS Income (Ex GST) | F9: TVS Income (Inc GST) | G9: Avg Bid Value | H9: Avg Take Rate %
B10: AP/TS | C10: =COUNTIF('Conversion Analytics (Master)'!$C$4:$C$4317, B10) | D10: =SUMIF('Conversion Analytics (Master)'!$C$4:$C$4317, B10, 'Conversion Analytics (Master)'!$I$4:$I$4317) | E10: =SUMIF('Conversion Analytics (Master)'!$C$4:$C$4317, B10, 'Conversion Analytics (Master)'!$M$4:$M$4317) | F10: =SUMIF('Conversion Analytics (Master)'!$C$4:$C$4317, B10, 'Conversion Analytics (Master)'!$N$4:$N$4317) | G10: =IF(C10>0, D10/C10, 0) | H10: =IF(D10>0, E10/D10, 0)
B11: Kerala | C11: =COUNTIF('Conversion Analytics (Master)'!$C$4:$C$4317, B11) | D11: =SUMIF('Conversion Analytics (Master)'!$C$4:$C$4317, B11, 'Conversion Analytics (Master)'!$I$4:$I$4317) | E11: =SUMIF('Conversion Analytics (Master)'!$C$4:$C$4317, B11, 'Conversion Analytics (Master)'!$M$4:$M$4317) | F11: =SUMIF('Conversion Analytics (Master)'!$C$4:$C$4317, B11, 'Conversion Analytics (Master)'!$N$4:$N$4317) | G11: =IF(C11>0, D11/C11, 0) | H11: =IF(D11>0, E11/D11, 0)
B12: TN | C12: =COUNTIF('Conversion Analytics (Master)'!$C$4:$C$4317, B12) | D12: =SUMIF('Conversion Analytics (Master)'!$C$4:$C$4317, B12, 'Conversion Analytics (Master)'!$I$4:$I$4317) | E12: =SUMIF('Conversion Analytics (Master)'!$C$4:$C$4317, B12, 'Conversion Analytics (Master)'!$M$4:$M$4317) | F12: =SUMIF('Conversion Analytics (Master)'!$C$4:$C$4317, B12, 'Conversion Analytics (Master)'!$N$4:$N$4317) | G12: =IF(C12>0, D12/C12, 0) | H12: =IF(D12>0, E12/D12, 0)
B13: TOTAL | C13: =SUM(C10:C12) | D13: =SUM(D10:D12) | E13: =SUM(E10:E12) | F13: =SUM(F10:F12) | G13: =IF(C13>0, D13/C13, 0) | H13: =IF(D13>0, E13/D13, 0)

Sheet Conversion Analytics (Master)
A1: TVS Certified - Conversion Analytics Master Dataset
A2: January to September 2026 Analytical Inventory Profile (4,314 Converted Units)
A3: FY | B3: Month | C3: State | D3: Vehicle Number | E3: Make | F3: Model | G3: Year | H3: Odometer | I3: Final Bid Value | J3: Seller Name | K3: Seller Segment | L3: Buyer Name | M3: Total Income (ex. GST) | N3: Total Income | O3: TVS Margin %
A4: FY26 | B4: Jan | C4: AP/TS | D4: AP31AS1112 | E4: HYUNDAI | F4: Getz | G4: 2007 | H4: 77543 | I4: 55000 | J4: Exchange VIZAG | K4: Captive | L4: Gadi Sri Bharathi | M4: 4237.29 | N4: 5000 | O4: =IF(AND(ISNUMBER(M4), ISNUMBER(I4), I4>0), M4/I4, "")
A5: FY26 | B5: Jan | C5: AP/TS | D5: AP31CS7594 | E5: HONDA | F5: Mobilio | G5: 2014 | H5: 98056 | I5: 265000 | J5: Exchange VIZAG | K5: Captive | L5: Siva Reddy Gudla | M5: 12711.86 | N5: 15000 | O5: =IF(AND(ISNUMBER(M5), ISNUMBER(I5), I5>0), M5/I5, "")
A6: FY26 | B6: Jan | C6: AP/TS | D6: TS09EY7211 | E6: NISSAN | F6: Micra | G6: 2017 | H6: 113473 | I6: 190000 | J6: Exchange HYDERABAD | K6: Captive | L6: Viswanadhapalli Aravind | M6: 8474.58 | N6: 10000 | O6: =IF(AND(ISNUMBER(M6), ISNUMBER(I6), I6>0), M6/I6, "")
A7: FY26 | B7: Jan | C7: AP/TS | D7: AP31CE7777 | E7: RENAULT | F7: Scala | G7: 2012 | H7: 255641 | I7: 97000 | J7: Exchange VIZAG | K7: Captive | L7: Kaki Dinesh Kumar | M7: 5932.2 | N7: 7000 | O7: =IF(AND(ISNUMBER(M7), ISNUMBER(I7), I7>0), M7/I7, "")
A8: FY26 | B8: Jan | C8: AP/TS | D8: AP31DF2198 | E8: HONDA | F8: Jazz | G8: 2016 | H8: 41567 | I8: 327500 | J8: Exchange VIZAG | K8: Captive | L8: Chukka Satish | M8: 10593.22 | N8: 12500 | O8: =IF(AND(ISNUMBER(M8), ISNUMBER(I8), I8>0), M8/I8, "")
A9: FY26 | B9: Jan | C9: AP/TS | D9: AP31BM4257 | E9: CHEVROLET | F9: Spark | G9: 2015 | H9: 141008 | I9: 50000 | J9: Kesireddi Saikiran | K9: Non-Captive | L9: Siva Reddy Gudla | M9: 4237.29 | N9: 5000 | O9: =IF(AND(ISNUMBER(M9), ISNUMBER(I9), I9>0), M9/I9, "")
A10: FY26 | B10: Jan | C10: AP/TS | D10: TS08GV4028 | E10: HONDA | F10: Amaze | G10: 2019 | H10: 74555 | I10: 380000 | J10: Exchange HYDERABAD | K10: Captive | L10: Ganothula Brahma Reddy | M10: 8474.58 | N10: 10000 | O10: =IF(AND(ISNUMBER(M10), ISNUMBER(I10), I10>0), M10/I10, "")
A11: FY26 | B11: Jan | C11: AP/TS | D11: TS09EB2697 | E11: HONDA | F11: City | G11: 2014 | H11: 158986 | I11: 265000 | J11: Exchange HYDERABAD | K11: Captive | L11: Uppari Sandeep Kumar | M11: 8474.58 | N11: 10000 | O11: =IF(AND(ISNUMBER(M11), ISNUMBER(I11), I11>0), M11/I11, "")
A12: FY26 | B12: Jan | C12: AP/TS | D12: TS11EC4656 | E12: HONDA | F12: Amaze | G12: 2015 | H12: 178445 | I12: 215000 | J12: Exchange HYDERABAD | K12: Captive | L12: Puneet Gupta | M12: 8474.58 | N12: 10000 | O12: =IF(AND(ISNUMBER(M12), ISNUMBER(I12), I12>0), M12/I12, "")
A13: FY26 | B13: Jan | C13: AP/TS | D13: AP39JV0286 | E13: TATA | F13: Tiago | G13: 2021 | H13: 58833 | I13: 335000 | J13: Exchange VIJAYAWADA | K13: Captive | L13: Naga Suresh Polukonda | M13: 8474.58 | N13: 10000 | O13: =IF(AND(ISNUMBER(M13), ISNUMBER(I13), I13>0), M13/I13, "")
A14: FY26 | B14: Jan | C14: AP/TS | D14: AP31DD1661 | E14: HONDA | F14: Jazz | G14: 2015 | H14: 132923 | I14: 240000 | J14: Exchange VIZAG | K14: Captive | L14: Raju Avaala | M14: 8474.58 | N14: 10000 | O14: =IF(AND(ISNUMBER(M14), ISNUMBER(I14), I14>0), M14/I14, "")
A15: FY26 | B15: Jan | C15: AP/TS | D15: AP31EP0888 | E15: HONDA | F15: Amaze | G15: 2018 | H15: 85923 | I15: 400000 | J15: Exchange VIZAG | K15: Captive | L15: Kaki Dinesh Kumar | M15: 12711.86 | N15: 15000 | O15: =IF(AND(ISNUMBER(M15), ISNUMBER(I15), I15>0), M15/I15, "")
... A318: FY26 | B318: Jan | C318: TN | D318: TN06B2738 | E318: HYUNDAI | F318: I10 | G318: 2010 | H318: 124567 | I318: 180000 | J318: Nirmal | K318: Non-Captive | L318: Ragupathy Cars | M318: 4237.29 | N318: 5000 | O318: =IF(AND(ISNUMBER(M318), ISNUMBER(I318), I318>0), M318/I318, "")
A319: FY26 | B319: Jan | C319: TN | D319: KL24L2932 | E319: HONDA | F319: Jazz | I319: 350000 | J319: Nippon Motor Corporation Pvt Ltd | K319: Non-Captive | L319: Shamnad AH | M319: 5932.2 | N319: 7000 | O319: =IF(AND(ISNUMBER(M319), ISNUMBER(I319), I319>0), M319/I319, "")
A320: FY26 | B320: Jan | C320: TN | D320: KL29M9531 | E320: HYUNDAI | F320: Verna | I320: 360000 | J320: Nippon Motor Corporation Pvt Ltd | K320: Non-Captive | L320: Shamnad AH | M320: 5932.2 | N320: 7000 | O320: =IF(AND(ISNUMBER(M320), ISNUMBER(I320), I320>0), M320/I320, "")
A321: FY26 | B321: Jan | C321: TN | D321: TN13H5670 | E321: TATA | F321: Tiago | G321: 2017 | H321: 79008 | I321: 250000 | J321: Lakshmi Tata | K321: Non-Captive | L321: Omega Car Zone | M321: 4237.29 | N321: 5000 | O321: =IF(AND(ISNUMBER(M321), ISNUMBER(I321), I321>0), M321/I321, "")
A322: FY26 | B322: Jan | C322: TN | D322: TN10BB1885 | E322: MARUTI SUZUKI | F322: Swift Dzire | G322: 2017 | H322: 110113 | I322: 400000 | J322: Lakshmi Tata | K322: Non-Captive | L322: Thiya Cars | M322: 4237.29 | N322: 5000 | O322: =IF(AND(ISNUMBER(M322), ISNUMBER(I322), I322>0), M322/I322, "")
A323: FY26 | B323: Jan | C323: TN | D323: TN12AM7659 | E323: RENAULT | F323: Kiger | G323: 2021 | H323: 41621 | I323: 260000 | J323: Lakshmi Tata | K323: Non-Captive | L323: Thiya Cars | M323: 4237.29 | N323: 5000 | O323: =IF(AND(ISNUMBER(M323), ISNUMBER(I323), I323>0), M323/I323, "")
A324: FY26 | B324: Jan | C324: TN | D324: TN02BC1360 | E324: RENAULT | F324: Logdy | G324: 2015 | H324: 67756 | I324: 300000 | J324: Lakshmi Tata | K324: Non-Captive | L324: Thiya Cars | M324: 4237.29 | N324: 5000 | O324: =IF(AND(ISNUMBER(M324), ISNUMBER(I324), I324>0), M324/I324, "")
A325: FY26 | B325: Jan | C325: TN | D325: TN13E0081 | E325: MARUTI SUZUKI | F325: Alto | G325: 2016 | H325: 44733 | I325: 150000 | J325: Lakshmi Tata | K325: Non-Captive | L325: Thiya Cars | M325: 4237.29 | N325: 5000 | O325: =IF(AND(ISNUMBER(M325), ISNUMBER(I325), I325>0), M325/I325, "")
A326: FY26 | B326: Jan | C326: TN | D326: TN12E7768 | E326: HYUNDAI | F326: Grand I10 | G326: 2014 | H326: 77642 | I326: 200000 | J326: Lakshmi Tata | K326: Non-Captive | L326: Thiya Cars | M326: 4237.29 | N326: 5000 | O326: =IF(AND(ISNUMBER(M326), ISNUMBER(I326), I326>0), M326/I326, "")
A327: FY26 | B327: Jan | C327: TN | D327: TN01U6000 | E327: MARUTI SUZUKI | F327: Alto | G327: 1998 | H327: 73444 | I327: 25000 | J327: Lakshmi Tata | K327: Non-Captive | L327: Thiya Cars | M327: 4237.29 | N327: 5000 | O327: =IF(AND(ISNUMBER(M327), ISNUMBER(I327), I327>0), M327/I327, "")
A328: FY26 | B328: Jan | C328: TN | D328: TN22CD7366 | E328: MARUTI SUZUKI | F328: Swift | G328: 2012 | H328: 55256 | I328: 160000 | J328: Lakshmi Tata | K328: Non-Captive | L328: Thiya Cars | M328: 4237.29 | N328: 5000 | O328: =IF(AND(ISNUMBER(M328), ISNUMBER(I328), I328>0), M328/I328, "")
A329: FY26 | B329: Jan | C329: TN | D329: TN07AL9019 | E329: HONDA | F329: City | G329: 2007 | H329: 94292 | I329: 100000 | J329: Lakshmi Tata | K329: Non-Captive | L329: Thiya Cars | M329: 4237.29 | N329: 5000 | O329: =IF(AND(ISNUMBER(M329), ISNUMBER(I329), I329>0), M329/I329, "")
A330: FY26 | B330: Jan | C330: TN | D330: TN18P1035 | E330: VOLKSWAGEN | F330: Polo | G330: 2012 | H330: 131005 | I330: 200000 | J330: Lakshmi Tata | K330: Non-Captive | L330: Thiya Cars | M330: 4237.29 | N330: 5000 | O330: =IF(AND(ISNUMBER(M330), ISNUMBER(I330), I330>0), M330/I330, "")
A331: FY26 | B331: Jan | C331: TN | D331: TN14W0344 | E331: TATA | F331: Tiago | G331: 2019 | H331: 72435 | I331: 270000 | J331: Lakshmi Tata | K331: Non-Captive | L331: Thiya Cars | M331: 4237.29 | N331: 5000 | O331: =IF(AND(ISNUMBER(M331), ISNUMBER(I331), I331>0), M331/I331, "")
A332: FY26 | B332: Jan | C332: TN | D332: TN03AB1023 | E332: TATA | F332: Tiago | G332: 2019 | H332: 116457 | I332: 260000 | J332: Lakshmi Tata | K332: Non-Captive | L332: Thiya Cars | M332: 4237.29 | N332: 5000 | O332: =IF(AND(ISNUMBER(M332), ISNUMBER(I332), I332>0), M332/I332, "")
... A334: FY26 | B334: Jan | C334: TN | D334: TN09BM0228 | E334: MARUTI SUZUKI | F334: Swift | G334: 2011 | H334: 174000 | I334: 185000 | J334: Khivraj Motor | K334: Non-Captive | L334: Balakrishnan | M334: 5084.75 | N334: 6000 | O334: =IF(AND(ISNUMBER(M334), ISNUMBER(I334), I334>0), M334/I334, "")
A335: FY26 | B335: Jan | C335: TN | D335: TN30BL266 | E335: MARUTI SUZUKI | F335: S-Cross | I335: 485000 | J335: Khivraj Motor | K335: Non-Captive | L335: Balakrishnan | M335: 5084.75 | N335: 6000 | O335: =IF(AND(ISNUMBER(M335), ISNUMBER(I335), I335>0), M335/I335, "")
A336: FY26 | B336: Jan | C336: TN | D336: TN09BA4646 | E336: MARUTI SUZUKI | F336: Zen | G336: 2009 | H336: 82508 | I336: 90000 | J336: Khivraj Motor | K336: Non-Captive | L336: AAA Cars | M336: 5084.75 | N336: 6000 | O336: =IF(AND(ISNUMBER(M336), ISNUMBER(I336), I336>0), M336/I336, "")
A337: FY26 | B337: Jan | C337: TN | D337: TN01BB5113 | E337: HYUNDAI | F337: Creta | G337: 2016 | H337: 67577 | I337: 465000 | J337: Khivraj Motor | K337: Non-Captive | L337: Aasim Motor | M337: 5084.75 | N337: 6000 | O337: =IF(AND(ISNUMBER(M337), ISNUMBER(I337), I337>0), M337/I337, "")
A338: FY26 | B338: Jan | C338: TN | D338: TN01AQ1698 | E338: MARUTI SUZUKI | F338: Swift Dzire | G338: 2011 | H338: 65103 | I338: 173000 | J338: Khivraj Motor | K338: Non-Captive | L338: Surendhar Cars | M338: 5084.75 | N338: 6000 | O338: =IF(AND(ISNUMBER(M338), ISNUMBER(I338), I338>0), M338/I338, "")
A339: FY26 | B339: Jan | C339: TN | D339: TN09CT3233 | E339: HYUNDAI | F339: Creta | G339: 2019 | H339: 44563 | I339: 530000 | J339: Harsha | K339: Non-Captive | L339: Pine Autos | M339: 5508.47 | N339: 6500 | O339: =IF(AND(ISNUMBER(M339), ISNUMBER(I339), I339>0), M339/I339, "")
A340: FY26 | B340: Jan | C340: TN | D340: KL04AG5541 | E340: MARUTI SUZUKI | F340: Ritz | I340: 210000 | J340: Nippon Motor Corporation Pvt Ltd | K340: Non-Captive | L340: Shamnad AH | M340: 5932.2 | N340: 7000 | O340: =IF(AND(ISNUMBER(M340), ISNUMBER(I340), I340>0), M340/I340, "")
A341: FY26 | B341: Jan | C341: TN | D341: TN01BP4170 | E341: HYUNDAI | F341: Aura | G341: 2022 | H341: 1974 | I341: 620000 | J341: Avis India | K341: Non-Captive | L341: Nirmal Cars | M341: 12711.86 | N341: 15000 | O341: =IF(AND(ISNUMBER(M341), ISNUMBER(I341), I341>0), M341/I341, "")
A342: FY26 | B342: Jan | C342: TN | D342: TN38CB0766 | E342: HONDA | F342: Amaze | G342: 2015 | H342: 65500 | I342: 190000 | J342: Sai Cars CBE | K342: Non-Captive | L342: KSM AUTO CONSULTING | M342: 4237.29 | N342: 5000 | O342: =IF(AND(ISNUMBER(M342), ISNUMBER(I342), I342>0), M342/I342, "")
A343: FY26 | B343: Jan | C343: TN | D343: TN01AC1548 | E343: TATA | F343: Indica | G343: 2006 | H343: 160671 | I343: 60000 | J343: Sai Cars CBE | K343: Non-Captive | L343: KSM AUTO CONSULTING | M343: 4237.29 | N343: 5000 | O343: =IF(AND(ISNUMBER(M343), ISNUMBER(I343), I343>0), M343/I343, "")
...

Sheet Conversion Data (Standard)
A1: TVS Certified - Monthly Conversion Report (Standard)
A2: January to September 2026 - Standard 13-Column Manager Reporting Template
A3: FY | B3: Month | C3: State | D3: Vehicle Number | E3: Make | F3: Model | G3: Year | H3: Odometer | I3: Final Bid Value | J3: Seller Name | K3: Seller Segment | L3: Buyer Name | M3: Total Income
A4: FY26 | B4: Jan | C4: AP/TS | D4: AP31AS1112 | E4: HYUNDAI | F4: Getz | G4: 2007 | H4: 77543 | I4: 55000 | J4: Exchange VIZAG | K4: Captive | L4: Gadi Sri Bharathi | M4: 4237.29
A5: FY26 | B5: Jan | C5: AP/TS | D5: AP31CS7594 | E5: HONDA | F5: Mobilio | G5: 2014 | H5: 98056 | I5: 265000 | J5: Exchange VIZAG | K5: Captive | L5: Siva Reddy Gudla | M5: 12711.86
A6: FY26 | B6: Jan | C6: AP/TS | D6: TS09EY7211 | E6: NISSAN | F6: Micra | G6: 2017 | H6: 113473 | I6: 190000 | J6: Exchange HYDERABAD | K6: Captive | L6: Viswanadhapalli Aravind | M6: 8474.58
A7: FY26 | B7: Jan | C7: AP/TS | D7: AP31CE7777 | E7: RENAULT | F7: Scala | G7: 2012 | H7: 255641 | I7: 97000 | J7: Exchange VIZAG | K7: Captive | L7: Kaki Dinesh Kumar | M7: 5932.2
A8: FY26 | B8: Jan | C8: AP/TS | D8: AP31DF2198 | E8: HONDA | F8: Jazz | G8: 2016 | H8: 41567 | I8: 327500 | J8: Exchange VIZAG | K8: Captive | L8: Chukka Satish | M8: 10593.22
A9: FY26 | B9: Jan | C9: AP/TS | D9: AP31BM4257 | E9: CHEVROLET | F9: Spark | G9: 2015 | H9: 141008 | I9: 50000 | J9: Kesireddi Saikiran | K9: Non-Captive | L9: Siva Reddy Gudla | M9: 4237.29
A10: FY26 | B10: Jan | C10: AP/TS | D10: TS08GV4028 | E10: HONDA | F10: Amaze | G10: 2019 | H10: 74555 | I10: 380000 | J10: Exchange HYDERABAD | K10: Captive | L10: Ganothula Brahma Reddy | M10: 8474.58
A11: FY26 | B11: Jan | C11: AP/TS | D11: TS09EB2697 | E11: HONDA | F11: City | G11: 2014 | H11: 158986 | I11: 265000 | J11: Exchange HYDERABAD | K11: Captive | L11: Uppari Sandeep Kumar | M11: 8474.58
A12: FY26 | B12: Jan | C12: AP/TS | D12: TS11EC4656 | E12: HONDA | F12: Amaze | G12: 2015 | H12: 178445 | I12: 215000 | J12: Exchange HYDERABAD | K12: Captive | L12: Puneet Gupta | M12: 8474.58
A13: FY26 | B13: Jan | C13: AP/TS | D13: AP39JV0286 | E13: TATA | F13: Tiago | G13: 2021 | H13: 58833 | I13: 335000 | J13: Exchange VIJAYAWADA | K13: Captive | L13: Naga Suresh Polukonda | M13: 8474.58
A14: FY26 | B14: Jan | C14: AP/TS | D14: AP31DD1661 | E14: HONDA | F14: Jazz | G14: 2015 | H14: 132923 | I14: 240000 | J14: Exchange VIZAG | K14: Captive | L14: Raju Avaala | M14: 8474.58
A15: FY26 | B15: Jan | C15: AP/TS | D15: AP31EP0888 | E15: HONDA | F15: Amaze | G15: 2018 | H15: 85923 | I15: 400000 | J15: Exchange VIZAG | K15: Captive | L15: Kaki Dinesh Kumar | M15: 12711.86
... A318: FY26 | B318: Jan | C318: TN | D318: TN06B2738 | E318: HYUNDAI | F318: I10 | G318: 2010 | H318: 124567 | I318: 180000 | J318: Nirmal | K318: Non-Captive | L318: Ragupathy Cars | M318: 4237.29
A319: FY26 | B319: Jan | C319: TN | D319: KL24L2932 | E319: HONDA | F319: Jazz | I319: 350000 | J319: Nippon Motor Corporation Pvt Ltd | K319: Non-Captive | L319: Shamnad AH | M319: 5932.2
A320: FY26 | B320: Jan | C320: TN | D320: KL29M9531 | E320: HYUNDAI | F320: Verna | I320: 360000 | J320: Nippon Motor Corporation Pvt Ltd | K320: Non-Captive | L320: Shamnad AH | M320: 5932.2
A321: FY26 | B321: Jan | C321: TN | D321: TN13H5670 | E321: TATA | F321: Tiago | G321: 2017 | H321: 79008 | I321: 250000 | J321: Lakshmi Tata | K321: Non-Captive | L321: Omega Car Zone | M321: 4237.29
A322: FY26 | B322: Jan | C322: TN | D322: TN10BB1885 | E322: MARUTI SUZUKI | F322: Swift Dzire | G322: 2017 | H322: 110113 | I322: 400000 | J322: Lakshmi Tata | K322: Non-Captive | L322: Thiya Cars | M322: 4237.29
A323: FY26 | B323: Jan | C323: TN | D323: TN12AM7659 | E323: RENAULT | F323: Kiger | G323: 2021 | H323: 41621 | I323: 260000 | J323: Lakshmi Tata | K323: Non-Captive | L323: Thiya Cars | M323: 4237.29
A324: FY26 | B324: Jan | C324: TN | D324: TN02BC1360 | E324: RENAULT | F324: Logdy | G324: 2015 | H324: 67756 | I324: 300000 | J324: Lakshmi Tata | K324: Non-Captive | L324: Thiya Cars | M324: 4237.29
A325: FY26 | B325: Jan | C325: TN | D325: TN13E0081 | E325: MARUTI SUZUKI | F325: Alto | G325: 2016 | H325: 44733 | I325: 150000 | J325: Lakshmi Tata | K325: Non-Captive | L325: Thiya Cars | M325: 4237.29
A326: FY26 | B326: Jan | C326: TN | D326: TN12E7768 | E326: HYUNDAI | F326: Grand I10 | G326: 2014 | H326: 77642 | I326: 200000 | J326: Lakshmi Tata | K326: Non-Captive | L326: Thiya Cars | M326: 4237.29
A327: FY26 | B327: Jan | C327: TN | D327: TN01U6000 | E327: MARUTI SUZUKI | F327: Alto | G327: 1998 | H327: 73444 | I327: 25000 | J327: Lakshmi Tata | K327: Non-Captive | L327: Thiya Cars | M327: 4237.29
A328: FY26 | B328: Jan | C328: TN | D328: TN22CD7366 | E328: MARUTI SUZUKI | F328: Swift | G328: 2012 | H328: 55256 | I328: 160000 | J328: Lakshmi Tata | K328: Non-Captive | L328: Thiya Cars | M328: 4237.29
A329: FY26 | B329: Jan | C329: TN | D329: TN07AL9019 | E329: HONDA | F329: City | G329: 2007 | H329: 94292 | I329: 100000 | J329: Lakshmi Tata | K329: Non-Captive | L329: Thiya Cars | M329: 4237.29
A330: FY26 | B330: Jan | C330: TN | D330: TN18P1035 | E330: VOLKSWAGEN | F330: Polo | G330: 2012 | H330: 131005 | I330: 200000 | J330: Lakshmi Tata | K330: Non-Captive | L330: Thiya Cars | M330: 4237.29
A331: FY26 | B331: Jan | C331: TN | D331: TN14W0344 | E331: TATA | F331: Tiago | G331: 2019 | H331: 72435 | I331: 270000 | J331: Lakshmi Tata | K331: Non-Captive | L331: Thiya Cars | M331: 4237.29
A332: FY26 | B332: Jan | C332: TN | D332: TN03AB1023 | E332: TATA | F332: Tiago | G332: 2019 | H332: 116457 | I332: 260000 | J332: Lakshmi Tata | K332: Non-Captive | L332: Thiya Cars | M332: 4237.29
... A334: FY26 | B334: Jan | C334: TN | D334: TN09BM0228 | E334: MARUTI SUZUKI | F334: Swift | G334: 2011 | H334: 174000 | I334: 185000 | J334: Khivraj Motor | K334: Non-Captive | L334: Balakrishnan | M334: 5084.75
A335: FY26 | B335: Jan | C335: TN | D335: TN30BL266 | E335: MARUTI SUZUKI | F335: S-Cross | I335: 485000 | J335: Khivraj Motor | K335: Non-Captive | L335: Balakrishnan | M335: 5084.75
A336: FY26 | B336: Jan | C336: TN | D336: TN09BA4646 | E336: MARUTI SUZUKI | F336: Zen | G336: 2009 | H336: 82508 | I336: 90000 | J336: Khivraj Motor | K336: Non-Captive | L336: AAA Cars | M336: 5084.75
A337: FY26 | B337: Jan | C337: TN | D337: TN01BB5113 | E337: HYUNDAI | F337: Creta | G337: 2016 | H337: 67577 | I337: 465000 | J337: Khivraj Motor | K337: Non-Captive | L337: Aasim Motor | M337: 5084.75
A338: FY26 | B338: Jan | C338: TN | D338: TN01AQ1698 | E338: MARUTI SUZUKI | F338: Swift Dzire | G338: 2011 | H338: 65103 | I338: 173000 | J338: Khivraj Motor | K338: Non-Captive | L338: Surendhar Cars | M338: 5084.75
A339: FY26 | B339: Jan | C339: TN | D339: TN09CT3233 | E339: HYUNDAI | F339: Creta | G339: 2019 | H339: 44563 | I339: 530000 | J339: Harsha | K339: Non-Captive | L339: Pine Autos | M339: 5508.47
A340: FY26 | B340: Jan | C340: TN | D340: KL04AG5541 | E340: MARUTI SUZUKI | F340: Ritz | I340: 210000 | J340: Nippon Motor Corporation Pvt Ltd | K340: Non-Captive | L340: Shamnad AH | M340: 5932.2
A341: FY26 | B341: Jan | C341: TN | D341: TN01BP4170 | E341: HYUNDAI | F341: Aura | G341: 2022 | H341: 1974 | I341: 620000 | J341: Avis India | K341: Non-Captive | L341: Nirmal Cars | M341: 12711.86
A342: FY26 | B342: Jan | C342: TN | D342: TN38CB0766 | E342: HONDA | F342: Amaze | G342: 2015 | H342: 65500 | I342: 190000 | J342: Sai Cars CBE | K342: Non-Captive | L342: KSM AUTO CONSULTING | M342: 4237.29
A343: FY26 | B343: Jan | C343: TN | D343: TN01AC1548 | E343: TATA | F343: Indica | G343: 2006 | H343: 160671 | I343: 60000 | J343: Sai Cars CBE | K343: Non-Captive | L343: KSM AUTO CONSULTING | M343: 4237.29
...

Sheet _MakeList
A1: BHARATBENZ
A2: CHEVROLET
A3: CITROEN
A4: DATSUN
A5: FIAT
A6: FORD
A7: HINDUSTAN MOTORS
A8: HONDA
A9: HYUNDAI
A10: JEEP
A11: KIA
A12: MAHINDRA
... A20: VOLKSWAGEN
